Workbook

Sheet Resumen
A1: Item | B1: Referencia | C1: Categoria | D1: Descripcion | E1: Ubicación | F1: Color | G1: Serie | H1: Unidad | I1: Cantidad | J1: Entrada | K1: Salida | L1: Saldo
A2: 1 | B2: =IF(IFERROR(VLOOKUP(A2,Kardex!$A$1:$K$1498,2,FALSE),"")=0,"",IFERROR(VLOOKUP(A2,Kardex!$A$1:$K$1498,2,FALSE),"")) -> 3779 | C2: =IFERROR(VLOOKUP(A2,Kardex!$A$1:$K$1498,3,FALSE),"") -> Perfil | D2: =IFERROR(VLOOKUP(A2,Kardex!$A$1:$K$1498,4,FALSE),"") -> Marco liso VP 3831 (38X30,9) mm | E2: =IFERROR(VLOOKUP(A2,Kardex!$A$1:$K$1498,5,FALSE),"") -> Banco | F2: =IFERROR(VLOOKUP(A2,Kardex!$A$1:$K$1498,6,FALSE),"") -> Blanco pintura | G2: =IFERROR(VLOOKUP(A2,Kardex!$A$1:$K$1498,7,FALSE),"") -> 3831 | H2: =IFERROR(VLOOKUP(A2,Kardex!$A$1:$K$1498,8,FALSE),"") -> un | I2: =IFERROR(VLOOKUP($A2,Kardex!$A$1:$L$1498,9,FALSE),"") -> 13 | J2: =IFERROR(VLOOKUP($A2,Kardex!$A$1:$L$1498,10,FALSE),"") -> 5 | K2: =IFERROR(VLOOKUP($A2,Kardex!$A$1:$L$1498,11,FALSE),"") -> 4 | L2: =IFERROR(VLOOKUP($A2,Kardex!$A$1:$L$1498,12,FALSE),"") -> 14
A3: 2 | B3: =IF(IFERROR(VLOOKUP(A3,Kardex!$A$1:$K$1498,2,FALSE),"")=0,"",IFERROR(VLOOKUP(A3,Kardex!$A$1:$K$1498,2,FALSE),"")) -> 3779 | C3: =IFERROR(VLOOKUP(A3,Kardex!$A$1:$K$1498,3,FALSE),"") -> Perfil | D3: =IFERROR(VLOOKUP(A3,Kardex!$A$1:$K$1498,4,FALSE),"") -> Marco liso VP 3831 (38X30,9) mm | E3: =IFERROR(VLOOKUP(A3,Kardex!$A$1:$K$1498,5,FALSE),"") -> Banco | F3: =IFERROR(VLOOKUP(A3,Kardex!$A$1:$K$1498,6,FALSE),"") -> Blanco mate | G3: =IFERROR(VLOOKUP(A3,Kardex!$A$1:$K$1498,7,FALSE),"") -> 3831 | H3: =IFERROR(VLOOKUP(A3,Kardex!$A$1:$K$1498,8,FALSE),"") -> un | I3: =IFERROR(VLOOKUP($A3,Kardex!$A$1:$L$1498,9,FALSE),"") -> 1 | J3: =IFERROR(VLOOKUP($A3,Kardex!$A$1:$L$1498,10,FALSE),"") -> 0 | K3: =IFERROR(VLOOKUP($A3,Kardex!$A$1:$L$1498,11,FALSE),"") -> 0 | L3: =IFERROR(VLOOKUP($A3,Kardex!$A$1:$L$1498,12,FALSE),"") -> 1
A4: 3 | B4: =IF(IFERROR(VLOOKUP(A4,Kardex!$A$1:$K$1498,2,FALSE),"")=0,"",IFERROR(VLOOKUP(A4,Kardex!$A$1:$K$1498,2,FALSE),"")) -> 3780 | C4: =IFERROR(VLOOKUP(A4,Kardex!$A$1:$K$1498,3,FALSE),"") -> Perfil | D4: =IFERROR(VLOOKUP(A4,Kardex!$A$1:$K$1498,4,FALSE),"") -> Marco autorroscante VP 3831 (38X30,9) mm | E4: =IFERROR(VLOOKUP(A4,Kardex!$A$1:$K$1498,5,FALSE),"") -> Banco | F4: =IFERROR(VLOOKUP(A4,Kardex!$A$1:$K$1498,6,FALSE),"") -> Blanco pintura | G4: =IFERROR(VLOOKUP(A4,Kardex!$A$1:$K$1498,7,FALSE),"") -> 3831 | H4: =IFERROR(VLOOKUP(A4,Kardex!$A$1:$K$1498,8,FALSE),"") -> un | I4: =IFERROR(VLOOKUP($A4,Kardex!$A$1:$L$1498,9,FALSE),"") -> 11 | J4: =IFERROR(VLOOKUP($A4,Kardex!$A$1:$L$1498,10,FALSE),"") -> 0 | K4: =IFERROR(VLOOKUP($A4,Kardex!$A$1:$L$1498,11,FALSE),"") -> 3 | L4: =IFERROR(VLOOKUP($A4,Kardex!$A$1:$L$1498,12,FALSE),"") -> 8
A5: 4 | B5: =IF(IFERROR(VLOOKUP(A5,Kardex!$A$1:$K$1498,2,FALSE),"")=0,"",IFERROR(VLOOKUP(A5,Kardex!$A$1:$K$1498,2,FALSE),"")) -> 2409 | C5: =IFERROR(VLOOKUP(A5,Kardex!$A$1:$K$1498,3,FALSE),"") -> Perfil | D5: =IFERROR(VLOOKUP(A5,Kardex!$A$1:$K$1498,4,FALSE),"") -> Sillar alfajia VP 3831 (103,2X37,1) mm | E5: =IFERROR(VLOOKUP(A5,Kardex!$A$1:$K$1498,5,FALSE),"") -> Banco | F5: =IFERROR(VLOOKUP(A5,Kardex!$A$1:$K$1498,6,FALSE),"") -> Blanco pintura | G5: =IFERROR(VLOOKUP(A5,Kardex!$A$1:$K$1498,7,FALSE),"") -> 3831 | H5: =IFERROR(VLOOKUP(A5,Kardex!$A$1:$K$1498,8,FALSE),"") -> un | I5: =IFERROR(VLOOKUP($A5,Kardex!$A$1:$L$1498,9,FALSE),"") -> 0 | J5: =IFERROR(VLOOKUP($A5,Kardex!$A$1:$L$1498,10,FALSE),"") -> 0 | K5: =IFERROR(VLOOKUP($A5,Kardex!$A$1:$L$1498,11,FALSE),"") -> 0 | L5: =IFERROR(VLOOKUP($A5,Kardex!$A$1:$L$1498,12,FALSE),"") -> 0
A6: 5 | B6: =IF(IFERROR(VLOOKUP(A6,Kardex!$A$1:$K$1498,2,FALSE),"")=0,"",IFERROR(VLOOKUP(A6,Kardex!$A$1:$K$1498,2,FALSE),"")) -> 2409 | C6: =IFERROR(VLOOKUP(A6,Kardex!$A$1:$K$1498,3,FALSE),"") -> Perfil | D6: =IFERROR(VLOOKUP(A6,Kardex!$A$1:$K$1498,4,FALSE),"") -> Sillar alfajia VP 3831 (103,2X37,1) mm | E6: =IFERROR(VLOOKUP(A6,Kardex!$A$1:$K$1498,5,FALSE),"") -> Banco | F6: =IFERROR(VLOOKUP(A6,Kardex!$A$1:$K$1498,6,FALSE),"") -> Blanco mate | G6: =IFERROR(VLOOKUP(A6,Kardex!$A$1:$K$1498,7,FALSE),"") -> 3831 | H6: =IFERROR(VLOOKUP(A6,Kardex!$A$1:$K$1498,8,FALSE),"") -> un | I6: =IFERROR(VLOOKUP($A6,Kardex!$A$1:$L$1498,9,FALSE),"") -> 0 | J6: =IFERROR(VLOOKUP($A6,Kardex!$A$1:$L$1498,10,FALSE),"") -> 6 | K6: =IFERROR(VLOOKUP($A6,Kardex!$A$1:$L$1498,11,FALSE),"") -> 0 | L6: =IFERROR(VLOOKUP($A6,Kardex!$A$1:$L$1498,12,FALSE),"") -> 6
A7: 6 | B7: =IF(IFERROR(VLOOKUP(A7,Kardex!$A$1:$K$1498,2,FALSE),"")=0,"",IFERROR(VLOOKUP(A7,Kardex!$A$1:$K$1498,2,FALSE),"")) -> 3788 | C7: =IFERROR(VLOOKUP(A7,Kardex!$A$1:$K$1498,3,FALSE),"") -> Perfil | D7: =IFERROR(VLOOKUP(A7,Kardex!$A$1:$K$1498,4,FALSE),"") -> Divisor VP 3831 (48X38) mm | E7: =IFERROR(VLOOKUP(A7,Kardex!$A$1:$K$1498,5,FALSE),"") -> Banco | F7: =IFERROR(VLOOKUP(A7,Kardex!$A$1:$K$1498,6,FALSE),"") -> Blanco pintura | G7: =IFERROR(VLOOKUP(A7,Kardex!$A$1:$K$1498,7,FALSE),"") -> 3831 | H7: =IFERROR(VLOOKUP(A7,Kardex!$A$1:$K$1498,8,FALSE),"") -> un | I7: =IFERROR(VLOOKUP($A7,Kardex!$A$1:$L$1498,9,FALSE),"") -> 0 | J7: =IFERROR(VLOOKUP($A7,Kardex!$A$1:$L$1498,10,FALSE),"") -> 14 | K7: =IFERROR(VLOOKUP($A7,Kardex!$A$1:$L$1498,11,FALSE),"") -> 5 | L7: =IFERROR(VLOOKUP($A7,Kardex!$A$1:$L$1498,12,FALSE),"") -> 9
A8: 7 | B8: =IF(IFERROR(VLOOKUP(A8,Kardex!$A$1:$K$1498,2,FALSE),"")=0,"",IFERROR(VLOOKUP(A8,Kardex!$A$1:$K$1498,2,FALSE),"")) -> 3789 | C8: =IFERROR(VLOOKUP(A8,Kardex!$A$1:$K$1498,3,FALSE),"") -> Perfil | D8: =IFERROR(VLOOKUP(A8,Kardex!$A$1:$K$1498,4,FALSE),"") -> Marco nave VP 3831 (46X38) mm | E8: =IFERROR(VLOOKUP(A8,Kardex!$A$1:$K$1498,5,FALSE),"") -> Banco | F8: =IFERROR(VLOOKUP(A8,Kardex!$A$1:$K$1498,6,FALSE),"") -> Blanco pintura | G8: =IFERROR(VLOOKUP(A8,Kardex!$A$1:$K$1498,7,FALSE),"") -> 3831 | H8: =IFERROR(VLOOKUP(A8,Kardex!$A$1:$K$1498,8,FALSE),"") -> un | I8: =IFERROR(VLOOKUP($A8,Kardex!$A$1:$L$1498,9,FALSE),"") -> 28 | J8: =IFERROR(VLOOKUP($A8,Kardex!$A$1:$L$1498,10,FALSE),"") -> 0 | K8: =IFERROR(VLOOKUP($A8,Kardex!$A$1:$L$1498,11,FALSE),"") -> 3 | L8: =IFERROR(VLOOKUP($A8,Kardex!$A$1:$L$1498,12,FALSE),"") -> 25
A9: 8 | B9: =IF(IFERROR(VLOOKUP(A9,Kardex!$A$1:$K$1498,2,FALSE),"")=0,"",IFERROR(VLOOKUP(A9,Kardex!$A$1:$K$1498,2,FALSE),"")) -> 2810 | C9: =IFERROR(VLOOKUP(A9,Kardex!$A$1:$K$1498,3,FALSE),"") -> Perfil | D9: =IFERROR(VLOOKUP(A9,Kardex!$A$1:$K$1498,4,FALSE),"") -> Adaptador VP 3831 (37,8X23,3) mm | E9: =IFERROR(VLOOKUP(A9,Kardex!$A$1:$K$1498,5,FALSE),"") -> Banco | F9: =IFERROR(VLOOKUP(A9,Kardex!$A$1:$K$1498,6,FALSE),"") -> Blanco pintura | G9: =IFERROR(VLOOKUP(A9,Kardex!$A$1:$K$1498,7,FALSE),"") -> 3831 | H9: =IFERROR(VLOOKUP(A9,Kardex!$A$1:$K$1498,8,FALSE),"") -> un | I9: =IFERROR(VLOOKUP($A9,Kardex!$A$1:$L$1498,9,FALSE),"") -> 41 | J9: =IFERROR(VLOOKUP($A9,Kardex!$A$1:$L$1498,10,FALSE),"") -> 1 | K9: =IFERROR(VLOOKUP($A9,Kardex!$A$1:$L$1498,11,FALSE),"") -> 0 | L9: =IFERROR(VLOOKUP($A9,Kardex!$A$1:$L$1498,12,FALSE),"") -> 42
A10: 9 | B10: =IF(IFERROR(VLOOKUP(A10,Kardex!$A$1:$K$1498,2,FALSE),"")=0,"",IFERROR(VLOOKUP(A10,Kardex!$A$1:$K$1498,2,FALSE),"")) -> 3774 | C10: =IFERROR(VLOOKUP(A10,Kardex!$A$1:$K$1498,3,FALSE),"") -> Perfil | D10: =IFERROR(VLOOKUP(A10,Kardex!$A$1:$K$1498,4,FALSE),"") -> Pisavidrio plano VP 3831 (29,2X18) mm | E10: =IFERROR(VLOOKUP(A10,Kardex!$A$1:$K$1498,5,FALSE),"") -> Banco | F10: =IFERROR(VLOOKUP(A10,Kardex!$A$1:$K$1498,6,FALSE),"") -> Blanco pintura | G10: =IFERROR(VLOOKUP(A10,Kardex!$A$1:$K$1498,7,FALSE),"") -> 3831 | H10: =IFERROR(VLOOKUP(A10,Kardex!$A$1:$K$1498,8,FALSE),"") -> un | I10: =IFERROR(VLOOKUP($A10,Kardex!$A$1:$L$1498,9,FALSE),"") -> 0 | J10: =IFERROR(VLOOKUP($A10,Kardex!$A$1:$L$1498,10,FALSE),"") -> 0 | K10: =IFERROR(VLOOKUP($A10,Kardex!$A$1:$L$1498,11,FALSE),"") -> 0 | L10: =IFERROR(VLOOKUP($A10,Kardex!$A$1:$L$1498,12,FALSE),"") -> 0
A11: 10 | B11: =IF(IFERROR(VLOOKUP(A11,Kardex!$A$1:$K$1498,2,FALSE),"")=0,"",IFERROR(VLOOKUP(A11,Kardex!$A$1:$K$1498,2,FALSE),"")) -> 3785 | C11: =IFERROR(VLOOKUP(A11,Kardex!$A$1:$K$1498,3,FALSE),"") -> Perfil | D11: =IFERROR(VLOOKUP(A11,Kardex!$A$1:$K$1498,4,FALSE),"") -> Pisavidrio curvo VP 3831 (29,1X18) mm | E11: =IFERROR(VLOOKUP(A11,Kardex!$A$1:$K$1498,5,FALSE),"") -> Banco | F11: =IFERROR(VLOOKUP(A11,Kardex!$A$1:$K$1498,6,FALSE),"") -> Blanco pintura | G11: =IFERROR(VLOOKUP(A11,Kardex!$A$1:$K$1498,7,FALSE),"") -> 3831 | H11: =IFERROR(VLOOKUP(A11,Kardex!$A$1:$K$1498,8,FALSE),"") -> un | I11: =IFERROR(VLOOKUP($A11,Kardex!$A$1:$L$1498,9,FALSE),"") -> 0 | J11: =IFERROR(VLOOKUP($A11,Kardex!$A$1:$L$1498,10,FALSE),"") -> 30 | K11: =IFERROR(VLOOKUP($A11,Kardex!$A$1:$L$1498,11,FALSE),"") -> 16 | L11: =IFERROR(VLOOKUP($A11,Kardex!$A$1:$L$1498,12,FALSE),"") -> 14
A12: 11 | B12: =IF(IFERROR(VLOOKUP(A12,Kardex!$A$1:$K$1498,2,FALSE),"")=0,"",IFERROR(VLOOKUP(A12,Kardex!$A$1:$K$1498,2,FALSE),"")) -> 2999 | C12: =IFERROR(VLOOKUP(A12,Kardex!$A$1:$K$1498,3,FALSE),"") -> Perfil | D12: =IFERROR(VLOOKUP(A12,Kardex!$A$1:$K$1498,4,FALSE),"") -> Pisavidrio plano 10 mm VP 3831 (29,2X18,3) mm | E12: =IFERROR(VLOOKUP(A12,Kardex!$A$1:$K$1498,5,FALSE),"") -> Banco | F12: =IFERROR(VLOOKUP(A12,Kardex!$A$1:$K$1498,6,FALSE),"") -> Blanco pintura | G12: =IFERROR(VLOOKUP(A12,Kardex!$A$1:$K$1498,7,FALSE),"") -> 3831 | H12: =IFERROR(VLOOKUP(A12,Kardex!$A$1:$K$1498,8,FALSE),"") -> un | I12: =IFERROR(VLOOKUP($A12,Kardex!$A$1:$L$1498,9,FALSE),"") -> 0 | J12: =IFERROR(VLOOKUP($A12,Kardex!$A$1:$L$1498,10,FALSE),"") -> 0 | K12: =IFERROR(VLOOKUP($A12,Kardex!$A$1:$L$1498,11,FALSE),"") -> 0 | L12: =IFERROR(VLOOKUP($A12,Kardex!$A$1:$L$1498,12,FALSE),"") -> 0
A13: 12 | B13: =IF(IFERROR(VLOOKUP(A13,Kardex!$A$1:$K$1498,2,FALSE),"")=0,"",IFERROR(VLOOKUP(A13,Kardex!$A$1:$K$1498,2,FALSE),"")) -> 3698 | C13: =IFERROR(VLOOKUP(A13,Kardex!$A$1:$K$1498,3,FALSE),"") -> Perfil | D13: =IFERROR(VLOOKUP(A13,Kardex!$A$1:$K$1498,4,FALSE),"") -> Pisavidrio 30 mm VP (29X17,5) mm | E13: =IFERROR(VLOOKUP(A13,Kardex!$A$1:$K$1498,5,FALSE),"") -> Banco | F13: =IFERROR(VLOOKUP(A13,Kardex!$A$1:$K$1498,6,FALSE),"") -> Blanco pintura | G13: =IFERROR(VLOOKUP(A13,Kardex!$A$1:$K$1498,7,FALSE),"") -> 3831 | H13: =IFERROR(VLOOKUP(A13,Kardex!$A$1:$K$1498,8,FALSE),"") -> un | I13: =IFERROR(VLOOKUP($A13,Kardex!$A$1:$L$1498,9,FALSE),"") -> 0 | J13: =IFERROR(VLOOKUP($A13,Kardex!$A$1:$L$1498,10,FALSE),"") -> 0 | K13: =IFERROR(VLOOKUP($A13,Kardex!$A$1:$L$1498,11,FALSE),"") -> 0 | L13: =IFERROR(VLOOKUP($A13,Kardex!$A$1:$L$1498,12,FALSE),"") -> 0
... A223: 222 | B223: =IF(IFERROR(VLOOKUP(A223,Kardex!$A$1:$K$1498,2,FALSE),"")=0,"",IFERROR(VLOOKUP(A223,Kardex!$A$1:$K$1498,2,FALSE),"")) | C223: =IFERROR(VLOOKUP(A223,Kardex!$A$1:$K$1498,3,FALSE),"") | D223: =IFERROR(VLOOKUP(A223,Kardex!$A$1:$K$1498,4,FALSE),"") | E223: =IFERROR(VLOOKUP(A223,Kardex!$A$1:$K$1498,5,FALSE),"") | F223: =IFERROR(VLOOKUP(A223,Kardex!$A$1:$K$1498,6,FALSE),"") | G223: =IFERROR(VLOOKUP(A223,Kardex!$A$1:$K$1498,7,FALSE),"") | H223: =IFERROR(VLOOKUP(A223,Kardex!$A$1:$K$1498,8,FALSE),"") | I223: =IFERROR(VLOOKUP($A223,Kardex!$A$1:$L$1498,9,FALSE),"") | J223: =IFERROR(VLOOKUP($A223,Kardex!$A$1:$L$1498,10,FALSE),"") | K223: =IFERROR(VLOOKUP($A223,Kardex!$A$1:$L$1498,11,FALSE),"") | L223: =IFERROR(VLOOKUP($A223,Kardex!$A$1:$L$1498,12,FALSE),"")

Sheet Portatiles
B3: No. | C3: Placa | D3: Caja | E3: Caja2 | F3: Caja y placa | G3: Placa3 | H3: Responsable
B4: 1 | C4: 95141024781 | D4: 24781 | E4: x | F4: x | G4: x | H4: Daniel
B5: 2 | C5: 95141024782 | D5: 24782
B6: 3 | C6: 95141024815 | D6: 24815 | E6: x | F6: x | G6: x | H6: Daniel
B7: 4 | C7: 95141024831 | D7: 24831 | E7: x | F7: x | G7: x | H7: Fernando
B8: 5 | C8: 95141024843 | D8: 24843 | G8: x | H8: Fernando
B9: 6 | C9: 95141024859 | D9: 24859 | G9: x | H9: Daniel
B10: 7 | C10: 95141024890 | D10: 24890 | E10: x | F10: x | G10: x | H10: Fernando
B11: 8 | C11: 95141024893 | D11: 24893 | E11: x | F11: x | G11: x | H11: Daniel
B12: 9 | C12: 95141024919 | D12: 24919 | E12: x | F12: x | G12: x | H12: Fernando
B13: 10 | C13: 95141024937 | D13: 24937 | E13: x | F13: x | G13: x | H13: Daniel
B14: 11 | C14: 95141024986 | D14: 24986 | E14: x | F14: x | G14: x | H14: Fernando
B15: 12 | C15: 95141024987 | D15: 24987 | E15: x
B16: 13 | C16: 95141024996 | D16: 24996 | E16: x
B17: 14 | C17: 95141025022 | D17: 25022 | E17: x | F17: x | G17: x | H17: Daniel
B18: 15 | C18: 95141025025 | D18: 25025 | E18: x | F18: x | G18: x | H18: Daniel
B19: 16 | C19: 95141025033 | D19: 25033 | E19: x | F19: x | G19: x | H19: Daniel
B20: 17 | C20: 95141025035 | D20: 25035 | E20: x | F20: x | G20: x | H20: Daniel
B21: 18 | C21: 95141025051 | D21: 25051 | E21: x | F21: x | G21: x | H21: Fernando
B22: 19 | C22: 95141025056 | D22: 25056 | E22: x | F22: x | G22: x | H22: Fernando
B23: 20 | C23: 95141025085 | D23: 25085 | E23: x | F23: x | G23: x | H23: Daniel
B24: Total | E24: =COUNTA(E4:E23) -> 17 | F24: =COUNTA(F4:F23) -> 15 | G24: =COUNTA(G4:G23) -> 17

Sheet Kardex
A1: Item | B1: Referencia | C1: Categoria | D1: Descripcion | E1: Ubicación | F1: Color | G1: Serie | H1: Unidad | I1: Cantidad | J1: Entrada | K1: Salida | L1: Saldo
A2: 1 | B2: 3779 | C2: Perfil | D2: Marco liso VP 3831 (38X30,9) mm | E2: Banco | F2: Blanco pintura | G2: 3831 | H2: un | I2: 13 | J2: =+J8 -> 5 | K2: =+K8 -> 4 | L2: =+I2+J2-K2 -> 14
A3: Fecha | C3: Descripcion | J3: Entrada | K3: Salida | L3: Saldo
A4: 46052 | C4: Sandoval | J4: 5 | M4: 5
A5: 46064 | C5: Marco ventana | K5: 3
A6: 46100 | C6: Marco ventana | K6: 1
A8: Subtotal | J8: =SUM(J4:J7) -> 5 | K8: =SUM(K4:K7) -> 4 | L8: =SUM(L4:L7) -> 0
A9: 2 | B9: 3779 | C9: Perfil | D9: Marco liso VP 3831 (38X30,9) mm | E9: Banco | F9: Blanco mate | G9: 3831 | H9: un | I9: 1 | J9: =+J14 -> 0 | K9: =+K14 -> 0 | L9: =+I9+J9-K9 -> 1
A10: Fecha | C10: Descripcion | J10: Entrada | K10: Salida | L10: Saldo
A14: Subtotal | J14: =SUM(J11:J13) -> 0 | K14: =SUM(K11:K13) -> 0 | L14: =SUM(L11:L13) -> 0
A15: 3 | B15: 3780 | C15: Perfil | D15: Marco autorroscante VP 3831 (38X30,9) mm | E15: Banco | F15: Blanco pintura | G15: 3831 | H15: un | I15: 11 | J15: =+J20 -> 0 | K15: =+K20 -> 3 | L15: =+I15+J15-K15 -> 8
A16: Fecha | C16: Descripcion | J16: Entrada | K16: Salida | L16: Saldo
A17: 46064 | C17: Marco ventana | K17: 2 | M17: 4
A18: 46100 | C18: Marco ventana | K18: 1
A20: Subtotal | J20: =SUM(J17:J19) -> 0 | K20: =SUM(K17:K19) -> 3 | L20: =SUM(L17:L19) -> 0
A21: 4 | B21: 2409 | C21: Perfil | D21: Sillar alfajia VP 3831 (103,2X37,1) mm | E21: Banco | F21: Blanco pintura | G21: 3831 | H21: un | J21: =+J26 -> 0 | K21: =+K26 -> 0 | L21: =+I21+J21-K21 -> 0
A22: Fecha | C22: Descripcion | J22: Entrada | K22: Salida | L22: Saldo
A26: Subtotal | J26: =SUM(J23:J25) -> 0 | K26: =SUM(K23:K25) -> 0 | L26: =SUM(L23:L25) -> 0
A27: 5 | B27: 2409 | C27: Perfil | D27: Sillar alfajia VP 3831 (103,2X37,1) mm | E27: Banco | F27: Blanco mate | G27: 3831 | H27: un | J27: =+J32 -> 6 | K27: =+K32 -> 0 | L27: =+I27+J27-K27 -> 6
A28: Fecha | C28: Descripcion | J28: Entrada | K28: Salida | L28: Saldo
A29: 46107 | C29: Inventario | J29: 6
A32: Subtotal | J32: =SUM(J29:J31) -> 6 | K32: =SUM(K29:K31) -> 0 | L32: =SUM(L29:L31) -> 0
A33: 6 | B33: 3788 | C33: Perfil | D33: Divisor VP 3831 (48X38) mm | E33: Banco | F33: Blanco pintura | G33: 3831 | H33: un | J33: =+J38 -> 14 | K33: =+K38 -> 5 | L33: =+I33+J33-K33 -> 9
A34: Fecha | C34: Descripcion | J34: Entrada | K34: Salida | L34: Saldo
A35: 46052 | C35: Sandoval | J35: =84/6 -> 14
A36: 46064 | C36: marco ventana | K36: 5
A38: Subtotal | J38: =SUM(J35:J37) -> 14 | K38: =SUM(K35:K37) -> 5 | L38: =SUM(L35:L37) -> 0
A39: 7 | B39: 3789 | C39: Perfil | D39: Marco nave VP 3831 (46X38) mm | E39: Banco | F39: Blanco pintura | G39: 3831 | H39: un | I39: 28 | J39: =+J44 -> 0 | K39: =+K44 -> 3 | L39: =+I39+J39-K39 -> 25
A40: Fecha | C40: Descripcion | J40: Entrada | K40: Salida | L40: Saldo
A41: 46088 | C41: Ventana proyectante con batiente | K41: 2
A42: 46104 | C42: Ventana proyectante con batiente | K42: 1
A44: Subtotal | J44: =SUM(J41:J43) -> 0 | K44: =SUM(K41:K43) -> 3 | L44: =SUM(L41:L43) -> 0
A45: 8 | B45: 2810 | C45: Perfil | D45: Adaptador VP 3831 (37,8X23,3) mm | E45: Banco | F45: Blanco pintura | G45: 3831 | H45: un | I45: 41 | J45: =+J50 -> 1 | K45: =+K50 -> 0 | L45: =+I45+J45-K45 -> 42
A46: Fecha | C46: Descripcion | J46: Entrada | K46: Salida | L46: Saldo
A47: 46052 | C47: Sandoval | J47: 1
A50: Subtotal | J50: =SUM(J47:J49) -> 1 | K50: =SUM(K47:K49) -> 0 | L50: =SUM(L47:L49) -> 0
A51: 9 | B51: 3774 | C51: Perfil | D51: Pisavidrio plano VP 3831 (29,2X18) mm | E51: Banco | F51: Blanco pintura | G51: 3831 | H51: un | J51: =+J56 -> 0 | K51: =+K56 -> 0 | L51: =+I51+J51-K51 -> 0
A52: Fecha | C52: Descripcion | J52: Entrada | K52: Salida | L52: Saldo
A56: Subtotal | J56: =SUM(J53:J55) -> 0 | K56: =SUM(K53:K55) -> 0 | L56: =SUM(L53:L55) -> 0
A57: 10 | B57: 3785 | C57: Perfil | D57: Pisavidrio curvo VP 3831 (29,1X18) mm | E57: Banco | F57: Blanco pintura | G57: 3831 | H57: un | J57: =+J66 -> 30 | K57: =+K66 -> 16 | L57: =+I57+J57-K57 -> 14
...

Sheet Hoja5
B5: HERRAMIENTA Y MATERIAL
B6: Items | C6: Descripcion | D6: Cantidad
B7: 1 | C7: Protector de respirador N95 | D7: 1
B8: 2 | C8: Guantes nitrilo | D8: 1
B9: 3 | C9: Overoles
C10: Talla S | D10: 1
C11: Talla M | D11: 3
B12: 4 | C12: Guantes de carnaza | D12: 3
B13: 5 | C13: Escoba | D13: 1
B14: 6 | C14: Guantes caña alta Goliat por par | D14: 43
B15: 7 | C15: Gafas de seguridad | D15: 3
B16: 8 | C16: Glock tamaño carta | D16: 1
B17: 9 | C17: Botas de seguridad
C18: Talla 42 | D18: 2
B19: 10 | C19: Bisagra de barra antipanico | D19: 1
B20: 11 | C20: Empaque U
C21: 4mm | D21: 11
B22: AULA
B23: Items | C23: Descripcion | D23: Cantidad
B24: 1 | C24: Sillas
C25: Estudiantil
C26: Negra | D26: 36
C27: Verde | D27: 33
C28: Docente
C29: Ejecutiva | D29: 3
C30: Verde | D30: 1
C31: Plasticas | D31: 1
B32: 2 | C32: Blokers | D32: 2
B33: 3 | C33: Gabinetes metalicos | D33: 3
B34: 4 | C34: Caja de madera | D34: 1
B35: 5 | C35: Televisor | D35: 1
B36: 6 | C36: Mesa
C37: Estudiantil | D37: 17
C38: Escritorios | D38: 5
B39: 7 | C39: Cable HDMI | D39: 1
B40: 8 | C40: Tablero | D40: 1
B41: 9 | C41: Botiquin | D41: 1
B42: 10 | C42: Gabinetes de madera | D42: 1
B43: 11 | C43: Iluminarias | D43: 9
B44: 12 | C44: Router | D44: 1
...

Sheet Hoja1
A4: Item | B4: Referencia | C4: Descripcion | D4: Color | E4: Serie | F4: Cantidad | G4: Entrada | H4: Salida
A5: 1 | B5: 3779 | C5: Marco liso VP 3831 (38X30,9) mm | D5: Blanco pintura | E5: 3831 | F5: 13
A6: 2 | B6: 3780 | C6: Marco autorroscante VP 3831 (38X30,9) mm | D6: Blanco pintura | E6: 3831 | F6: 11
A7: 3 | B7: 2409 | C7: Sillar alfajia VP 3831 (103,2X37,1) mm | D7: Blanco pintura | E7: 3831
A8: 4 | B8: 3788 | C8: Divisor VP 3831 (48X38) mm | D8: Blanco pintura | E8: 3831
A9: 5 | B9: 3789 | C9: Marco nave VP 3831 (46X38) mm | D9: Blanco pintura | E9: 3831 | F9: 28
A10: 6 | B10: 2810 | C10: Adaptador VP 3831 (37,8X23,3) mm | D10: Blanco pintura | E10: 3831 | F10: 41
A11: 7 | B11: 3774 | C11: Pisavidrio plano VP 3831 (29,2X18) mm | D11: Blanco pintura | E11: 3831
A12: 8 | B12: 3785 | C12: Pisavidrio curvo VP 3831 (29,1X18) mm | D12: Blanco pintura | E12: 3831
A13: 9 | B13: 2999 | C13: Pisavidrio plano 10 mm VP 3831 (29,2X18,3) mm | D13: Blanco pintura | E13: 3831
A14: 10 | B14: 3698 | C14: Pisavidrio 30 mm VP (29X17,5) mm | D14: Blanco pintura | E14: 3831
A15: 11 | B15: 3790 | C15: Esquinero VP 3831 (38X18) mm | D15: Blanco pintura | E15: 3831
A16: 12 | B16: 3784 | C16: Tubular con adaptador VP 3831 (1 1/2X1 1/2)" (55,8X38) mm | D16: Blanco pintura | E16: 3831
A17: 13 | B17: 4131 | C17: Tubular con adaptador VP 3831 (2X1 1/2)" (73,9X38) mm | D17: Blanco pintura | E17: 3831
A18: 14 | B18: 3783 | C18: Tubular con adaptador VP 3831 (3X1 1/2)" (104,3X38) mm | D18: Blanco pintura | E18: 3831
A19: 15 | B19: 3897 | C19: Tubular con doble adaptador VP 3831 (1 1/2X1 1/2)" (73,4X38) mm | D19: Blanco pintura | E19: 3831
A20: 16 | B20: 4130 | C20: Tubular con doble adaptador VP 3831 (3X1 1/2)" (126,2X38) mm | D20: Blanco pintura | E20: 3831
A21: 17 | B21: 3862 | C21: Cabezal P.C. 2044/744 (62,60X18,00) mm | D21: Blanco pintura | E21: 744 | F21: 8
A22: 18 | B22: 3861 | C22: Sillar P.C. 2044/744 (64,25X16,95) mm | D22: Blanco pintura | E22: 744 | F22: 8
A23: 19 | B23: 3861 | C23: Sillar P.C. 2044/744 (64,25X16,95) mm | D23: Blanco mate | E23: 744 | F23: 1
A24: 20 | B24: 4748 | C24: Sillar Alfajia P.C. 2044/744 (99,39X21,79) mm | D24: Blanco pintura | E24: 744
A25: 21 | B25: 3863 | C25: Jamba P.C. 2044/744 (60X20,8) mm | D25: Blanco pintura | E25: 744 | F25: 10
A26: 22 | B26: 3855 | C26: Horizontal superior P.C. 2044/744 (34,2X17) mm | D26: Blanco pintura | E26: 744 | F26: 15
A27: 23 | B27: 2894 | C27: Horizontal inferior P.C. 2044/744 (49,4X18,2) mm | D27: Blanco pintura | E27: 744 | F27: 11
A28: 24 | B28: 3903 | C28: Traslape P.C. 2044/744 (44,3X20) mm | D28: Blanco pintura | E28: 744 | F28: 7
A29: 25 | B29: 3902 | C29: Enganche P.C:. 2044/744 (34X26,5) mm | D29: Blanco pintura | E29: 744 | F29: 9
A30: 26 | B30: 2003 | C30: Adaptador P.C. 2044/744 (23,2X17) mm | D30: Blanco pintura | E30: 744
A31: 27 | B31: 3854 | C31: Cabezal V.C. 4020/5020 (52,7X19) mm | D31: Blanco pintura | E31: 5020
A32: 28 | B32: 2829 | C32: Sillar V.C. 4020/5020 (51,4X27) mm | D32: Blanco pintura | E32: 5020
A33: 29 | B33: 3853 | C33: Sillar alfajia V.C. 4020/5020 (99X33,2) mm | D33: Blanco pintura | E33: 5020
A34: 30 | B34: 2831 | C34: Jamba V.C. 4020/5020 (50X19,4) mm | D34: Blanco pintura | E34: 5020
A35: 31 | B35: 2833 | C35: Horizontal superior/inferior V.C. 4020/5020 (38,5X15,4) mm | D35: Blanco pintura | E35: 5020 | F35: 6
A36: 32 | B36: 2832 | C36: Traslape V.C. 4020/5020 (23,6X18,3) mm | D36: Blanco pintura | E36: 5020
A37: 33 | B37: 3852 | C37: Traslape reforzado V.C. 4020/5020 (42X18) mm | D37: Blanco pintura | E37: 5020
A38: 34 | B38: 2834 | C38: Enganche V.C. 4020/5020 (24,8X25,6) mm | D38: Blanco pintura | E38: 5020
A39: 35 | B39: 1865 | C39: Adaptador V.C. 4020/5020 (22X16) mm | D39: Blanco pintura | E39: 5020
A40: 36 | B40: 3894 | C40: Tubular con aleta descentrada (3X1)" (72,6X37,4) mm | D40: Blanco pintura | E40: T A
A41: 37 | B41: 3892 | C41: Tubular con doble aleta descentrada (3X1)" (72,6X49,4) mm | D41: Blanco pintura | E41: T 2A
A42: 38 | B42: 3895 | C42: Tubular (3X1)" (76,2X25,4) mm espesor 1,2 mm | D42: Blanco mate | E42: T | F42: 2
A43: 39 | B43: 2837 | C43: Tubular (3X1 1/2)" (76,2X38) mm espesor 1,1 mm | D43: Blanco pintura | E43: T | F43: 1

Sheet Hoja3
C2: HERRAMIENTA
C3: Ítems | D3: Descripción | E3: Cantidad
C4: 1.00 | D4: Taladros
C5: 1.01 | D5: Taladro Bosch 3/8 inalámbrico | E5: 3
C6: 1.02 | D6: Taladro Dewalt 3/8 inalámbrico | E6: 1
C7: 1.03 | D7: Taladro Dewalt 1/2 inalámbrico | E7: 1
C8: 1.04 | D8: Taladro percutor Dewalt 1/2 eléctrico | E8: 1
C9: 1.05 | D9: Cargado Bosch | E9: 1
C10: 1.06 | D10: Cargado Dewalt DCB107 | E10: 3
C11: 1.07 | D11: Batería DCB120 | E11: 2
C12: 2.00 | D12: Herramienta manual
C13: 2.01 | D13: Destornillador de estrella 8 plgs | E13: 1
C14: 2.02 | D14: Destornillador de estrella de 6 plgs | E14: 4
C15: 2.03 | D15: Destornillador plano de 6 plgs | E15: 2
C16: 2.04 | D16: Lima triangular | E16: 2
C17: 2.05 | D17: Lima cuchillo | E17: 1
C18: 2.06 | D18: Lima media caña | E18: 2
C19: 2.06 | D19: Tester | E19: 1
C20: 2.07 | D20: Alicates | E20: 1
C21: 2.08 | D21: Alicate punta larga | E21: 1
C22: 2.09 | D22: Brocha de 1 plg | E22: 1
C23: 2.10 | D23: Espátula de 3 plgs | E23: 1
C24: 2.11 | D24: Espátula de 2 plgs | E24: 2
... C37: 2.24 | D37: Punta de taladro plana | E37: 1
C44: HERRAMIENTA Y MATERIAL
C45: Ítems | D45: Descripción | E45: Cantidad | F45: Entrada | G45: Salida | H45: Saldo
C46: 1.00 | D46: Protector de respirador N95 X3 | E46: 1 | H46: =+E46+F46-G46 -> 1
C47: 2.00 | D47: Guantes nitrilo strat | E47: 1 | H47: =+E47+F47-G47 -> 1
C48: 3.00 | D48: Overoles | H48: =+E48+F48-G48 -> 0
C49: 3.01 | D49: Overol talla S | E49: 2 | H49: =+E49+F49-G49 -> 2
C50: 3.02 | D50: Overol talla M | E50: 3 | H50: =+E50+F50-G50 -> 3
C51: 4.00 | D51: Guantes de carnaza | E51: 3 | H51: =+E51+F51-G51 -> 3
C52: 5.00 | D52: Escoba | E52: 1 | H52: =+E52+F52-G52 -> 1
C53: 6.00 | D53: Guantes caña alta Goliat por par | E53: 46 | G53: 1 | H53: =+E53+F53-G53 -> 45
C54: 7.00 | D54: Gafas de seguridad | E54: 3 | H54: =+E54+F54-G54 -> 3
C55: 8.00 | D55: Block tamaño carta | E55: 1 | H55: =+E55+F55-G55 -> 1
C56: 9.00 | D56: Botas de seguridad | H56: =+E56+F56-G56 -> 0
C57: 9.01 | D57: Botas talla 42 | E57: 2 | H57: =+E57+F57-G57 -> 2
C58: 10.00 | D58: Caja de barra antipánico | E58: 1 | H58: =+E58+F58-G58 -> 1
C59: 11.00 | D59: Disco de pulidora | E59: 1 | H59: =+E59+F59-G59 -> 1
...
